<?xml version="1.0" ?>
<robot name="stick_bot">

  <!-- Segmento base -->
  <link name="segment0">
    <inertial>
      <mass value="0.5"/>
      <inertia ixx="0.01" iyy="0.01" izz="0.01" ixy="0" ixz="0" iyz="0"/>
    </inertial>
    <visual>
      <geometry>
        <cylinder length="0.3" radius="0.05"/>
      </geometry>
      <origin xyz="0 0 0.15" rpy="0 0 0"/>
      <material name="blue"/>
    </visual>
    <collision>
      <geometry>
        <cylinder length="0.3" radius="0.05"/>
      </geometry>
      <origin xyz="0 0 0.15" rpy="0 0 0"/>
    </collision>
  </link>

  <!-- Segmento 1 -->
  <link name="segment1">
    <inertial>
      <mass value="0.5"/>
      <inertia ixx="0.01" iyy="0.01" izz="0.01" ixy="0" ixz="0" iyz="0"/>
    </inertial>
    <visual>
      <geometry>
        <cylinder length="0.3" radius="0.05"/>
      </geometry>
      <origin xyz="0 0 0.15" rpy="0 0 0"/>
      <material name="red"/>
    </visual>
    <collision>
      <geometry>
        <cylinder length="0.3" radius="0.05"/>
      </geometry>
      <origin xyz="0 0 0.15" rpy="0 0 0"/>
    </collision>
  </link>

  <!-- Joint 0 -> 1 -->
  <joint name="joint1" type="revolute">
    <parent link="segment0"/>
    <child link="segment1"/>
    <origin xyz="0 0 0.3" rpy="0 0 0"/>
    <axis xyz="0 1 0"/>
    <limit lower="-1.57" upper="1.57" effort="5" velocity="2"/>
  </joint>

  <!-- Segmento 2 -->
  <link name="segment2">
    <inertial>
      <mass value="0.5"/>
      <inertia ixx="0.01" iyy="0.01" izz="0.01" ixy="0" ixz="0" iyz="0"/>
    </inertial>
    <visual>
      <geometry>
        <cylinder length="0.3" radius="0.05"/>
      </geometry>
      <origin xyz="0 0 0.15" rpy="0 0 0"/>
      <material name="green"/>
    </visual>
    <collision>
      <geometry>
        <cylinder length="0.3" radius="0.05"/>
      </geometry>
      <origin xyz="0 0 0.15" rpy="0 0 0"/>
    </collision>
  </link>

  <!-- Joint 1 -> 2 -->
  <joint name="joint2" type="revolute">
    <parent link="segment1"/>
    <child link="segment2"/>
    <origin xyz="0 0 0.3" rpy="0 0 0"/>
    <axis xyz="0 1 0"/>
    <limit lower="-1.57" upper="1.57" effort="5" velocity="2"/>
  </joint>

</robot>
